[INFO][2021-02-28 12:31:56,630][autoreload.py:612]Watching for file changes with StatReloader
[INFO][2021-02-28 12:32:08,101][autoreload.py:612]Watching for file changes with StatReloader
[INFO][2021-02-28 12:34:41,101][autoreload.py:236]D:\Program Files\JetBrains\shop_admin\adminDemo\urls.py changed, reloading.
[INFO][2021-02-28 12:34:42,308][autoreload.py:612]Watching for file changes with StatReloader
[INFO][2021-02-28 12:35:00,426][autoreload.py:236]D:\Program Files\JetBrains\shop_admin\adminDemo\urls.py changed, reloading.
[INFO][2021-02-28 15:06:13,019][autoreload.py:612]Watching for file changes with StatReloader
[INFO][2021-02-28 15:06:49,307][autoreload.py:612]Watching for file changes with StatReloader
[WARNING][2021-02-28 15:07:10,737][connectionpool.py:751]Retrying (Retry(total=2, connect=None, read=None, redirect=None, status=None)) after connection broken by 'NewConnectionError('<urllib3.connection.HTTPConnection object at 0x000002C7A54378B0>: Failed to establish a new connection: [WinError 10060] 由于连接方在一段时间后没有正确答复或连接的主机没有反应，连接尝试失败。')': /api/3/store/
[WARNING][2021-02-28 15:07:31,805][connectionpool.py:751]Retrying (Retry(total=1, connect=None, read=None, redirect=None, status=None)) after connection broken by 'NewConnectionError('<urllib3.connection.HTTPConnection object at 0x000002C7A5898EB0>: Failed to establish a new connection: [WinError 10060] 由于连接方在一段时间后没有正确答复或连接的主机没有反应，连接尝试失败。')': /api/3/store/
[WARNING][2021-02-28 15:07:52,853][connectionpool.py:751]Retrying (Retry(total=0, connect=None, read=None, redirect=None, status=None)) after connection broken by 'NewConnectionError('<urllib3.connection.HTTPConnection object at 0x000002C7A5898E50>: Failed to establish a new connection: [WinError 10060] 由于连接方在一段时间后没有正确答复或连接的主机没有反应，连接尝试失败。')': /api/3/store/
[INFO][2021-02-28 15:07:59,026][autoreload.py:236]D:\Program Files\JetBrains\shop_admin\adminDemo\urls.py changed, reloading.
[INFO][2021-02-28 15:08:01,966][autoreload.py:612]Watching for file changes with StatReloader
[WARNING][2021-02-28 15:08:33,130][log.py:224]Not Found: /swagger
[WARNING][2021-02-28 15:08:33,246][log.py:224]Not Found: /favicon.ico
[ERROR][2021-02-28 15:08:45,162][log.py:224]Internal Server Error: /swagger/
Traceback (most recent call last):
  File "D:\Python\PythonVirtualenv\adminDemo\lib\site-packages\django\core\handlers\exception.py", line 47, in inner
    response = get_response(request)
  File "D:\Python\PythonVirtualenv\adminDemo\lib\site-packages\django\core\handlers\base.py", line 202, in _get_response
    response = response.render()
  File "D:\Python\PythonVirtualenv\adminDemo\lib\site-packages\django\template\response.py", line 105, in render
    self.content = self.rendered_content
  File "D:\Python\PythonVirtualenv\adminDemo\lib\site-packages\rest_framework\response.py", line 70, in rendered_content
    ret = renderer.render(self.data, accepted_media_type, context)
  File "D:\Python\PythonVirtualenv\adminDemo\lib\site-packages\drf_yasg\renderers.py", line 73, in render
    return render_to_string(self.template, renderer_context, renderer_context['request'])
  File "D:\Python\PythonVirtualenv\adminDemo\lib\site-packages\django\template\loader.py", line 61, in render_to_string
    template = get_template(template_name, using=using)
  File "D:\Python\PythonVirtualenv\adminDemo\lib\site-packages\django\template\loader.py", line 19, in get_template
    raise TemplateDoesNotExist(template_name, chain=chain)
django.template.exceptions.TemplateDoesNotExist: drf-yasg/swagger-ui.html
[WARNING][2021-02-28 15:09:06,086][connectionpool.py:751]Retrying (Retry(total=2, connect=None, read=None, redirect=None, status=None)) after connection broken by 'NewConnectionError('<urllib3.connection.HTTPConnection object at 0x000001D9101D8640>: Failed to establish a new connection: [WinError 10060] 由于连接方在一段时间后没有正确答复或连接的主机没有反应，连接尝试失败。')': /api/3/store/
[WARNING][2021-02-28 15:09:27,157][connectionpool.py:751]Retrying (Retry(total=1, connect=None, read=None, redirect=None, status=None)) after connection broken by 'NewConnectionError('<urllib3.connection.HTTPConnection object at 0x000001D9102D45B0>: Failed to establish a new connection: [WinError 10060] 由于连接方在一段时间后没有正确答复或连接的主机没有反应，连接尝试失败。')': /api/3/store/
[WARNING][2021-02-28 15:09:48,186][connectionpool.py:751]Retrying (Retry(total=0, connect=None, read=None, redirect=None, status=None)) after connection broken by 'NewConnectionError('<urllib3.connection.HTTPConnection object at 0x000001D9102D4400>: Failed to establish a new connection: [WinError 10060] 由于连接方在一段时间后没有正确答复或连接的主机没有反应，连接尝试失败。')': /api/3/store/
[INFO][2021-02-28 15:10:25,463][autoreload.py:236]D:\Program Files\JetBrains\shop_admin\adminDemo\settings\com_settings.py changed, reloading.
[INFO][2021-02-28 15:10:27,059][autoreload.py:612]Watching for file changes with StatReloader
